Workbook
Name calen: Data!#REF!
Name diascal: Data!$L$1:$L$721
Name fecha2020: Data!$B$1:$B$1978
Name fechas: Data!$B$1:$B$517
Name fechas2: Data!$B$1:$B$882
Name fechas3: Data!$B$1:$B$517
Name fechass: Data!$B$1:$B$1612
Name fff: Data!$B$1:$B$1247
Name habil: Data!$I$1:$I$2
Name lugar: Data!$H$1:$H$2
Name papa: Data!$J$1:$J$2
Name plaz2: Data!$D$1:$D$2
Name recu: Data!$A$1:$A$2
Name SINO: Data!$G$1:$G$2
Name tipo: Data!$C$1:$C$3
Name tipo2: Data!$E$1:$E$2
Name TIPO3: Data!$C$2:$C$3
Name tipo4: Data!$F$1:$F$2
Name TIPODIA: Data!$K$1:$K$2

Sheet EO-usuario
N2: Plazo aplicable para | Q2: Lima
B5: PLAZOS DE RESOLUCIÓN Y NOTIFICACIÓN | L5: PLAZOS DE ELEVACIÓN DE APELACIÓN O QUEJA
C7: Fecha de reclamo | H7: 46308 | M7: Fecha de | N7: queja | O7: =IF(N7="Queja","3","5") -> 3 | Q7: 46318
H8: 44681
C9: Plazo para resolver | E9: 20 días hábiles | F9: =IF(E9="03 días hábiles","3",IF(E9="15 días hábiles",15,20)) -> 20 | H9: =WORKDAY.INTL(H7,F9,1,'No laborables'!$B7:$B286) -> 46336 | M9: Plazo para elevar | Q9: =WORKDAY.INTL(Q7,O7,1,'No laborables (2)'!$B7:$B298) -> 46323
C11: Plazo para notificar | F11: 5 | H11: =WORKDAY.INTL(H9,F11,1,'No laborables'!$B7:$B286) -> 46343
C13: Artículo 54.- Plazos de resolución de los reclamos Los reclamos presentados por los usuarios ante la empresa operadora serán resueltos en los siguientes plazos máximos: | M13: =IF(N7="Apelación",S15,S14) -> Artículo 74.- Remisión de la queja al TRASU El TRASU será el encargado de resolver las quejas que presenten los usuarios contra la primera instancia administrativa de las empresas operadoras. Presentada dicha solicitud en la empresa operadora, ésta deberá elevarla al TRASU en un plazo no mayor de tres (3) días hábiles contados a partir del día siguiente de su presentación, conjuntamente con sus descargos y el expediente correspondiente, organizado formalmente conforme a lo dispuesto en el artículo 77.
C14: =IF(E9="03 días hábiles",I14,IF(E9="15 días hábiles",I15,I16)) -> (…) 3. Hasta veinte (20) días hábiles, contados desde el día siguiente de su presentación ante la empresa operadora, en los demás casos. Para las materias de reclamo que hayan sido previstas en otras normas, se aplicará el plazo que haya sido señalado en las mismas, en caso contrario, se regirán por el plazo mayor que establece el presente Reglamento. | I14: 1. Hasta en tres (3) días hábiles, contados desde el día siguiente de su presentación ante la empresa operadora, en reclamos por: a. Calidad e idoneidad en la prestación del servicio, incluyendo la veracidad de la información brindada al usuario. b. Suspensión, corte o baja injustificada del servicio, incluyendo el corte del servicio público móvil y/o bloqueo del equipo terminal móvil, por uso prohibido del servicio en establecimientos penitenciarios. c. Falta de entrega del recibo o de la copia del recibo o de la facturación detallada solicitada por el usuario. (...) | S14: Artículo 74.- Remisión de la queja al TRASU El TRASU será el encargado de resolver las quejas que presenten los usuarios contra la primera instancia administrativa de las empresas operadoras. Presentada dicha solicitud en la empresa operadora, ésta deberá elevarla al TRASU en un plazo no mayor de tres (3) días hábiles contados a partir del día siguiente de su presentación, conjuntamente con sus descargos y el expediente correspondiente, organizado formalmente conforme a lo dispuesto en el artículo 77.
C15: Instrucciones | I15: (...) 2. Hasta en quince (15) días hábiles, contados desde el día siguiente de su presentación ante la empresa operadora, en reclamos por: a. Facturación cuyo monto reclamado sea de hasta 0.5 % de la Unidad Impositiva Tributaria. b. Tarjetas de pago. c. Instalación o activación del servicio. d. Traslado del servicio. (...) | M15: Instrucciones | S15: Artículo 61.- Remisión del recurso de apelación al TRASU Presentado el recurso de apelación, la empresa operadora cuenta con un plazo máximo de cinco (5) días hábiles contados desde el día siguiente de su presentación, para elevarlo al TRASU conjuntamente con sus descargos y el expediente correspondiente, organizado formalmente conforme a lo dispuesto en el artículo 77. Para tal efecto, la empresa operadora deberá adjuntar un informe que describa en términos precisos y conforme a los formatos aprobados por el TRASU, lo siguiente: 1. Motivo del reclamo. 2. Información sobre los reclamos y las pruebas actuadas según la materia del reclamo; y, 3. Pronunciamiento respecto a cada uno de los hechos expuestos en el recurso de apelación del usuario. El silencio, la respuesta evasiva o la negativa genérica y contradictoria podrán ser apreciados por el TRASU como reconocimiento de verdad de los hechos alegados por el usuario.
C16: 1. Ingresar la fecha presentación de reclamo | I16: (…) 3. Hasta veinte (20) días hábiles, contados desde el día siguiente de su presentación ante la empresa operadora, en los demás casos. Para las materias de reclamo que hayan sido previstas en otras normas, se aplicará el plazo que haya sido señalado en las mismas, en caso contrario, se regirán por el plazo mayor que establece el presente Reglamento. | M16: 1. Seleccionar si el escrito corresponde a una apelación o a una queja.
C17: 2. Seleccionar el plazo de resolución del reclamo de acuerdo al Reglamento. | M17: 2. Ingresar la fecha de la presentación de la apelación o queja.
B21: PLAZO PARA PRESENTAR RECURSO DE APELACIÓN
C23: Fecha de notificación | E23: 46100 | F23: 42736 | G23: 42736 | H23: 42736
E24: dejalo a
C25: Notificación fue realizada en día | H25: hábil
C27: Plazo para apelar | F27: =IF(H25="hábil",15,16) -> 15 | H27: =IF(Q2="Lima",(WORKDAY.INTL(E23,F27,1,'No laborables'!$B7:$B286)),(WORKDAY.INTL(E23,F27,1,'No laborables'!$C7:$C286))) -> 46122
C29: Artículo 58º.- Recurso de apelación y plazo para su interposición (…) El plazo para interponer el recurso de apelación no deberá exceder de quince (15) días hábiles contados desde el día siguiente de la notificación al usuario de la resolución de primera instancia.(...)
C30: Instrucciones
C31: 1. Ingresar la fecha de notificación.
C32: 2. Seleccionar si el día en que se realizó la notificación fue hábil o inhábil. | R32: Actualizado el | T32: =NOW() -> 46028.408

Sheet TRASU
N2: Plazo aplicable para Salas de | Q2: Lima
B5: PLAZOS DE RESOLUCIÓN PARA EL TRASU PARA RECURSOS DE APELACIÓN | L5: PLAZOS DE RESOLUCIÓN PARA EL TRASU PARA QUEJAS
C7: Fecha de inicio del expediente | H7: 46181 | M7: Fecha de inicio del expediente | Q7: 46315
C9: Plazo para resolver | D9: 15 días hábiles | F9: =IF(D9="15 días hábiles",15,25) -> 15 | H9: =IF($Q$2="Lima",(WORKDAY.INTL(H7,F9,1,'No laborables (2)'!$B7:$B298)),(WORKDAY.INTL(H7,F9,1,'No laborables (2)'!$C7:$C298))) -> 46203 | M9: Plazo para resolver | O9: 13 | Q9: =IF($Q$2="Lima",(WORKDAY.INTL(Q7,O9,1,'No laborables (2)'!$B7:$B298)),(WORKDAY.INTL(Q7,O9,1,'No laborables (2)'!$C7:$C298))) -> 46332
C11: Ampliación del Consejo Directivo (2017)* | E11: SI | F11: 120 | H11: =IF(E11="SI", IF($Q$2="Lima",(WORKDAY.INTL(H9,F11,1,'No laborables (2)'!$B7:$B298)),(WORKDAY.INTL(H9,F11,1,'No laborables (2)'!$C7:$C298)))," ") -> 46380 | M11: Ampliación del Consejo Directivo (2017)* | N11: SI | O11: 120 | Q11: =IF(N11="SI", IF($Q$2="Lima",(WORKDAY.INTL(Q9,O11,1,'No laborables (2)'!$B7:$B298)),(WORKDAY.INTL(Q9,O11,1,'No laborables (2)'!$C7:$C298)))," ") -> 46505
C13: Ampliación del Reglamento | F13: 20 | H13: =IF(E11="SI",IF($Q$2="Lima",(WORKDAY.INTL(H11,F13,1,'No laborables (2)'!$B7:$B298)),(WORKDAY.INTL(H11,F13,1,'No laborables (2)'!$C7:$C298))), IF($Q$2="Lima",(WORKDAY.INTL(H9,F13,1,'No laborables (2)'!$B7:$B298)),(WORKDAY.INTL(H9,F13,1,'No laborables (2)'!$C7:$C298)))) -> 46409 | M13: Ampliación del Reglamento | O13: 10 | Q13: =IF(N11="SI",IF($Q$2="Lima",(WORKDAY.INTL(Q11,O13,1,'No laborables (2)'!$B7:$B298)),(WORKDAY.INTL(Q11,O13,1,'No laborables (2)'!$C7:$C298))), IF($Q$2="Lima",(WORKDAY.INTL(Q9,O13,1,'No laborables (2)'!$B7:$B298)),(WORKDAY.INTL(Q9,O13,1,'No laborables (2)'!$C7:$C298)))) -> 46519
C15: Artículo 66.- Plazos de resolución El recurso de apelación presentado por el usuario será resuelto por el TRASU en los siguientes plazos máximos: | M15: Artículo 75.- Plazos de resolución de la queja La queja será resuelta dentro del plazo de trece (13) días hábiles contados desde el día siguiente a la fecha de su recepción por el TRASU. Excepcionalmente, cuando la complejidad del expediente lo amerite, e TRASU podrá, por única vez, ampliar el plazo para resolver dicha solicitud hasta en diez (10) días hábiles adicionales.
C16: =IF(D9="03 días hábiles",I16,IF(D9="15 días hábiles",I18,I19)) -> 1. Hasta en quince (15) días hábiles, contados desde el día siguiente de recibido el recurso por el TRASU, en los reclamos por: a. Suspensión, corte o baja injustificada del servicio, incluyendo el corte del servicio público móvil y/o bloqueo del equipo terminal móvil, por uso prohibido del servicio en estabelcimientos penitenciarios. b. Tarjetas de pago. c. Traslado del servicio. d. Falta de entrefa del recibo o de la copia del recibo o de la facturación detallada solicitada por el usuario. (...)
C17: Cuando la complejidad en la tramitación de un expediente lo amerite, el TRASU podrá, por una sola vez, ampliar en veinte (20) días hábiles adicionales el plazo para resolver. Para las materias de reclamo que hayan sido previstas en otras normas, se aplicará el plazo que haya sido señalado en las mismas, en caso contrario, se regirán por el plazo mayor que establece el presente Reglamento. | M17: =IF(N14="SI",R19," ")
C18: Instrucciones | I18: 1. Hasta en quince (15) días hábiles, contados desde el día siguiente de recibido el recurso por el TRASU, en los reclamos por: a. Suspensión, corte o baja injustificada del servicio, incluyendo el corte del servicio público móvil y/o bloqueo del equipo terminal móvil, por uso prohibido del servicio en estabelcimientos penitenciarios. b. Tarjetas de pago. c. Traslado del servicio. d. Falta de entrefa del recibo o de la copia del recibo o de la facturación detallada solicitada por el usuario. (...) | M18: Instrucciones
C19: 1. Ingresar la fecha de recepción del recurso por el TRASU. | I19: (…) 3. Hasta veinticinco (25) días hábiles, contados a partir del día siguiente de recibido el recurso por el TRASU, en los demás casos. | M19: 1. Ingresar la fecha de recepción de la queja por el TRASU.
C20: 2. Seleccionar el plazo de resolución del recurso de acuerdo al Reglamento. | M20: 2. Seleccionar si hay ampliación del plazo para resolución del Reglamento.
C21: 3. Seleccionar si hay ampliación del plazo para resolución del Reglamento.
B24: *Ampliación del plazo de resolución en 120 días hábiles para recursos de apelación y quejas cuyo vencimiento se encuentre entre el 20 de abril al 29 de diciembre de 2017 (Resolución N°055-2017-CD/OSIPTEL).
B25: =IF(E11="SI",B24," ") -> *Ampliación del plazo de resolución en 120 días hábiles para recursos de apelación y quejas cuyo vencimiento se encuentre entre el 20 de abril al 29 de diciembre de 2017 (Resolución N°055-2017-CD/OSIPTEL). | L25: =IF(N11="SI",B24," ") -> *Ampliación del plazo de resolución en 120 días hábiles para recursos de apelación y quejas cuyo vencimiento se encuentre entre el 20 de abril al 29 de diciembre de 2017 (Resolución N°055-2017-CD/OSIPTEL).
S26: Actualizado el | T26: =NOW() -> 46028.408

Sheet Calculadora libre
E2: Días hábiles para | G2: Lima
B5: CÁLCULO DE DÍAS HÁBILES / CALENDARIO
C7: Fecha inicial | E7: 46103
C9: Tipo de días a calcular | E9: Hábiles
C11: N° de días | E11: 15
E12: 30
C13: Fecha final | E13: =IF(G2="Lima",(IF(E9="Hábiles",(WORKDAY.INTL(E7,E11,1,'No laborables (2)'!$B7:$B298)),E7+E11)),(IF(E9="Hábiles",(WORKDAY.INTL(E7,E11,1,'No laborables (2)'!$C7:$C298)),E7+E11))) -> 46125
C15: Instrucciones
C16: 1. Ingresar la fecha de inicio para cálculo del plazo.
C17: 2. Seleccionar si el tipo de días a calcular.
C18: 3. Ingresar el número de días a calcular
I19: e

Sheet No laborables
B1: Días no laborables se aplican para:
B3: 1. Resolución y notificación de reclamos en primera instancia (No laborables solo Lima).
B4: 2. Presentación de recurso de apelación (No laborables todo el país).
B6: No laborables solo Lima | C6: No laborables todo el país | D6: Puerto Maldonado | E6: Trujillo | F6: Resolución Puerto Maldonado
B7: 42005 | C7: 42005 | D7: 42005 | E7: 42005 | F7: 42005
B8: 42006 | C8: 42006 | D8: 42006 | E8: 42006 | F8: 42006
B9: 42096 | C9: 42096 | D9: 42096 | E9: 42096 | F9: 42096
B10: 42097 | C10: 42097 | D10: 42097 | E10: 42097 | F10: 42097
B11: 42125 | C11: 42125 | D11: 42125 | E11: 42125 | F11: 42125
B12: 42184 | C12: 42184 | D12: 42184 | E12: 42184 | F12: 42184
B13: 42213 | C13: 42213 | D13: 42213 | E13: 42213 | F13: 42213
B14: 42214 | C14: 42214 | D14: 42214 | E14: 42214 | F14: 42214
B15: 42246 | C15: 42246 | D15: 42246 | E15: 42246 | F15: 42246
B16: 42285 | C16: 42285 | D16: 42285 | E16: 42285 | F16: 42285
B17: 42286 | F17: 42286
B18: 42309 | C18: 42309 | D18: 42309 | E18: 42309 | F18: 42309
B19: 42346 | C19: 42346 | D19: 42346 | E19: 42346 | F19: 42346
B20: 42363 | C20: 42363 | D20: 42363 | E20: 42363 | F20: 42363
B21: 42370 | C21: 42370 | D21: 42370 | E21: 42370 | F21: 42370
B22: 42453 | C22: 42453 | D22: 42453 | E22: 42453 | F22: 42453
B23: 42454 | C23: 42454 | D23: 42454 | E23: 42454 | F23: 42454
B24: 42491 | C24: 42491 | D24: 42491 | E24: 42491 | F24: 42491
B25: 42550 | C25: 42550 | D25: 42550 | E25: 42550 | F25: 42550
B26: 42579 | C26: 42579 | D26: 42579 | E26: 42579 | F26: 42579
B27: 42580 | C27: 42580 | D27: 42580 | E27: 42580 | F27: 42580
B28: 42612 | C28: 42612 | D28: 42612 | E28: 42612 | F28: 42612
B29: 42651 | C29: 42651 | D29: 42651 | E29: 42651 | F29: 42651
B30: 42675 | C30: 42675 | D30: 42675 | E30: 42675 | F30: 42675
B31: 42691 | F31: 42691
B32: 42692 | F32: 42692
B33: 42693 | F33: 42693
B34: 42712 | C34: 42712 | D34: 42712 | E34: 42712 | F34: 42712
B35: 42729 | C35: 42729 | D35: 42729 | E35: 42729 | F35: 42729
B36: 42736 | C36: 42736 | D36: 42736 | E36: 42736 | F36: 42736
B37: 42838 | C37: 42838 | D37: 42838 | E37: 42838 | F37: 42838
B38: 42839 | C38: 42839 | D38: 42839 | E38: 42839 | F38: 42839
B39: 42841 | C39: 42841 | D39: 42841 | E39: 42841 | F39: 42841
B40: 42856 | C40: 42856 | D40: 42856 | E40: 42856 | F40: 42856
B41: 42915 | C41: 42915 | D41: 42915 | E41: 42915 | F41: 42915
B42: 42944 | C42: 42944 | D42: 42944 | E42: 42944 | F42: 42944
...

Sheet No laborables (2)
B1: Días no laborables se aplican para:
B3: 1. Resolución y notificación de reclamos en segunda instancia.
B4: 2. Elevación de apelaciones y quejas.
B6: No laborables solo Lima | C6: No laborables todo el país | D6: Con feriados para sector público
B7: 42005 | C7: 42005
B8: 42006 | C8: 42006
B9: 42096 | C9: 42096
B10: 42097 | C10: 42097
B11: 42125 | C11: 42125
B12: 42184 | C12: 42184
B13: 42213 | C13: 42213
B14: 42214 | C14: 42214
B15: 42246 | C15: 42246
B16: 42285 | C16: 42285
B17: 42286
B18: 42309 | C18: 42309
B19: 42346 | C19: 42346
B20: 42363 | C20: 42363
B21: 42370 | C21: 42370
B22: 42453 | C22: 42453
B23: 42454 | C23: 42454
B24: 42491 | C24: 42491
B25: 42550 | C25: 42550
B26: 42579 | C26: 42579
B27: 42580 | C27: 42580
B28: 42612 | C28: 42612
B29: 42651 | C29: 42651
B30: 42675 | C30: 42675
B31: 42691
B32: 42692
B33: 42693
B34: 42712 | C34: 42712
B35: 42729 | C35: 42729
B36: 42736 | C36: 42736
B37: 42838 | C37: 42838
B38: 42839 | C38: 42839
B39: 42841 | C39: 42841
B40: 42856 | C40: 42856
B41: 42915 | C41: 42915
B42: 42916 | C42: 42916 | D42: Feriado para el sector público
...

Sheet Competencias
B2: COMPETENCIA SALAS UNIPERSONALES
B3: QUEJA | C3: Plazo de solución es de trece (13) días hábiles
C4: 1 | D4: Por infracción de plazos ( ER solicita se aplique el SAP)
C5: 2 | D5: Por suspensión o corte del servicio con reclamo en trámite
C6: 3 | D6: Por requerimiento de pago del importe reclamado o por negativa a recibir el pago del importe que no es reclamado.
C7: 4 | D7: Por negativa a recibir el reclamo, recurso de queja o por no otorgar el código de reclamo o queja.
C8: 5 | D8: Cualquier otro defecto en la tramitación que implique una transgresión normativa.
B9: APELACIÓN | C9: Cuyo plazo de solución sea de quince (15) días hábiles
C10: 1 | D10: Suspensión, corte o baja injustificada
C11: 2 | D11: Traslado del servicio
C12: 3 | D12: Tarjetas de pago físicas o virtuales
C13: 4 | D13: Falta de entrega de recibo o copia de recibo
C14: 5 | D14: Facturación detallada
C15: 6 | D15: Suspensión por Uso Prohibido
C16: 7 | D16: Desbloqueo de equipo
C17: 8 | D17: Cambio de titularidad
C18: 9 | D18: Facturación cuyo importe reclamado sea igual o menor al 0.5% de una UIT.
C19: 10 | D19: Portabilidad | E19: A | F19: Negativa a aceptar la solicitud de portabilidad
E20: B | F20: Rechazo a la Solicitud de portabilidad
E21: C | F21: Falta de consentimiento del abonado (portabilidad no solicitada)
C22: Cuyo plazo de solución sea veinticinco (25) días hábiles debido a que el importe reclamado sea mayor al 0.5% de una UIT pero no supere los S/100.00 soles (menor cuantía) incluido el cobro del servicio.
B23: COMPETENCIA SALAS COLEGIADAS*
B24: APELACIÓN | C24: Cuyo plazo de solución sea de veinticinco (25) días hábiles
C25: 1 | D25: Facturación cuyo importe reclamado sea mayor a S/. 100. Nuevos Soles.
C26: 2 | D26: Cobro del servicio cuando el importe reclamado sea mayor a S/. 100. Nuevos Soles.
C27: 3 | D27: Calidad
C28: 4 | D28: Idoneidad
C29: 5 | D29: Veracidad en la información
C30: 6 | D30: Instalación o activación
C31: 7 | D31: Contratación no solicitada
C32: 8 | D32: Incumplimiento de las condiciones contractuales
C33: 9 | D33: Incumplimiento de ofertas y promociones
C34: 10 | D34: Demás materias reclamables distintas a las detalladas en el punto anterior.
B36: *No obstante lo indicado en el presente cuadro, es preciso tener en cuenta en Informe N°00183-GAL/2016, de fecha 23 de junio de 2016, sobre las competencias de las Salas del TRASU, cuyas conclusiones son las siguientes: 1. La competencia atribuida a las Salas Unipersonales para conocer los expedientes de queja, menor cuantía, casos con plazo de resolución menor o en general, aquellos casos que actualmente vienen tramitando, no ha sido otorgada en forma exclusiva a dichas Salas. En tal sentido, es factible que las Salas Colegiadas conozcan dichos expedientes, en tanto, mantienen la competencia establecida en los artículos 2° y 3° del Reglamento del TRASU. 2. Es factible que los procedimientos administrativos sancionadores a ser conocidos por el TRASU, sean resueltos por las Salas Colegiadas, considerando que constituye una función del TRASU, y por ende de las salas que lo conforman, ejercer la facultad sancionadora establecida en el RFIS, conforme lo señalado en el numeral 3 del artículo 3° del Reglamento del TRASU.

Sheet Data
A1: apelación | B1: 42219 | C1: 03 días hábiles | D1: 03 días hábiles | E1: APELACIÓN | F1: 15 días hábiles | G1: SI | H1: Lima | I1: hábil | J1: Trujillo | K1: Hábiles | L1: 0
A2: queja | B2: 42220 | C2: 15 días hábiles | D2: 05 días hábiles | E2: QUEJA | F2: 25 días hábiles | G2: NO | H2: provincias | I2: inhábil | J2: Puerto Maldonado | K2: Calendario | L2: 1
B3: 42221 | C3: 20 días hábiles | L3: 2
B4: 42222 | L4: 3
B5: 42223 | L5: 4
B6: 42224 | L6: 5
B7: 42225 | L7: 6
B8: 42226 | L8: 7
B9: 42227 | L9: 8
B10: 42228 | L10: 9
B11: 42229 | L11: 10
B12: 42230 | L12: 11
B13: 42231 | L13: 12
B14: 42232 | L14: 13
B15: 42233 | L15: 14
... B721: 42939 | L721: 720
B722: 42940
B723: 42941
B724: 42942
B725: 42943
B726: 42944
B727: 42945
B728: 42946
B729: 42947
B730: 42948
B731: 42949
B732: 42950
B733: 42951
... B4534: 46752
